Configuring logging...
2025-05-17 03:34:22,443 - root - INFO - Logging configured successfully
2025-05-17 03:34:24,115 - root - INFO - Project Root: /Users/oliverga/Documents/personal/sworn
2025-05-17 03:34:24,115 - root - INFO - App Directory: /Users/oliverga/Documents/personal/sworn/app
2025-05-17 03:34:24,115 - root - INFO - 
--- IMPORTANT: Ensure your Celery broker (e.g., Redis) is running! ---

2025-05-17 03:34:24,116 - root - INFO - Initializing processes...
2025-05-17 03:34:24,116 - root - INFO - 
--- Starting Uvicorn in main process ---
2025-05-17 03:34:24,116 - root - INFO - Starting Uvicorn serverâ€¦
2025-05-17 03:34:24,211 - uvicorn.error - INFO - Started server process [17250]
2025-05-17 03:34:24,212 - uvicorn.error - INFO - Waiting for application startup.
2025-05-17 03:34:24,212 - uvicorn.error - INFO - Application startup complete.
2025-05-17 03:34:24,212 - uvicorn.error - INFO - Uvicorn running on http://0.0.0.0:8000 (Press CTRL+C to quit)
2025-05-17 03:34:27,434 - root - INFO - >>> [Dependency] Creating session...
2025-05-17 03:34:27,434 - root - INFO - >>> [Dependency] Session 4495504928 created.
2025-05-17 03:34:27,446 - root - INFO - SkillDefinitionRepository initialized.
2025-05-17 03:34:27,500 INFO sqlalchemy.engine.Engine select pg_catalog.version()
2025-05-17 03:34:27,500 - sqlalchemy.engine.Engine - INFO - select pg_catalog.version()
2025-05-17 03:34:27,500 INFO sqlalchemy.engine.Engine [raw sql] ()
2025-05-17 03:34:27,500 - sqlalchemy.engine.Engine - INFO - [raw sql] ()
2025-05-17 03:34:27,517 INFO sqlalchemy.engine.Engine select current_schema()
2025-05-17 03:34:27,517 - sqlalchemy.engine.Engine - INFO - select current_schema()
2025-05-17 03:34:27,517 INFO sqlalchemy.engine.Engine [raw sql] ()
2025-05-17 03:34:27,517 - sqlalchemy.engine.Engine - INFO - [raw sql] ()
2025-05-17 03:34:27,534 INFO sqlalchemy.engine.Engine show standard_conforming_strings
2025-05-17 03:34:27,534 - sqlalchemy.engine.Engine - INFO - show standard_conforming_strings
2025-05-17 03:34:27,534 INFO sqlalchemy.engine.Engine [raw sql] ()
2025-05-17 03:34:27,534 - sqlalchemy.engine.Engine - INFO - [raw sql] ()
2025-05-17 03:34:27,545 INFO sqlalchemy.engine.Engine BEGIN (implicit)
2025-05-17 03:34:27,545 - sqlalchemy.engine.Engine - INFO - BEGIN (implicit)
2025-05-17 03:34:27,545 INFO sqlalchemy.engine.Engine SELECT skill_definitions.id, skill_definitions.name, skill_definitions.description, skill_definitions.max_level, skill_definitions.themes, skill_definitions._metadata, skill_definitions.created_at, skill_definitions.updated_at 
FROM skill_definitions 
 LIMIT $1::INTEGER OFFSET $2::INTEGER
2025-05-17 03:34:27,545 - sqlalchemy.engine.Engine - INFO - SELECT skill_definitions.id, skill_definitions.name, skill_definitions.description, skill_definitions.max_level, skill_definitions.themes, skill_definitions._metadata, skill_definitions.created_at, skill_definitions.updated_at 
FROM skill_definitions 
 LIMIT $1::INTEGER OFFSET $2::INTEGER
2025-05-17 03:34:27,546 INFO sqlalchemy.engine.Engine [generated in 0.00006s] (100, 0)
2025-05-17 03:34:27,546 - sqlalchemy.engine.Engine - INFO - [generated in 0.00006s] (100, 0)
2025-05-17 03:34:27,555 - root - ERROR - >>> [Dependency] Exception escaped yield for session 4495504928: (sqlalchemy.dialects.postgresql.asyncpg.ProgrammingError) <class 'asyncpg.exceptions.UndefinedColumnError'>: column skill_definitions._metadata does not exist
[SQL: SELECT skill_definitions.id, skill_definitions.name, skill_definitions.description, skill_definitions.max_level, skill_definitions.themes, skill_definitions._metadata, skill_definitions.created_at, skill_definitions.updated_at 
FROM skill_definitions 
 LIMIT $1::INTEGER OFFSET $2::INTEGER]
[parameters: (100, 0)]
(Background on this error at: https://sqlalche.me/e/20/f405)
Traceback (most recent call last):
  File "/Users/oliverga/Documents/personal/sworn/venv/lib/python3.13/site-packages/sqlalchemy/dialects/postgresql/asyncpg.py", line 521, in _prepare_and_execute
    prepared_stmt, attributes = await adapt_connection._prepare(
                                ^^^^^^^^^^^^^^^^^^^^^^^^^^^^^^^^
        operation, self._invalidate_schema_cache_asof
        ^^^^^^^^^^^^^^^^^^^^^^^^^^^^^^^^^^^^^^^^^^^^^
    )
    ^
  File "/Users/oliverga/Documents/personal/sworn/venv/lib/python3.13/site-packages/sqlalchemy/dialects/postgresql/asyncpg.py", line 768, in _prepare
    prepared_stmt = await self._connection.prepare(
                    ^^^^^^^^^^^^^^^^^^^^^^^^^^^^^^^
        operation, name=self._prepared_statement_name_func()
        ^^^^^^^^^^^^^^^^^^^^^^^^^^^^^^^^^^^^^^^^^^^^^^^^^^^^
    )
    ^
  File "/Users/oliverga/Documents/personal/sworn/venv/lib/python3.13/site-packages/asyncpg/connection.py", line 635, in prepare
    return await self._prepare(
           ^^^^^^^^^^^^^^^^^^^^
    ...<5 lines>...
    )
    ^
  File "/Users/oliverga/Documents/personal/sworn/venv/lib/python3.13/site-packages/asyncpg/connection.py", line 653, in _prepare
    stmt = await self._get_statement(
           ^^^^^^^^^^^^^^^^^^^^^^^^^^
    ...<5 lines>...
    )
    ^
  File "/Users/oliverga/Documents/personal/sworn/venv/lib/python3.13/site-packages/asyncpg/connection.py", line 432, in _get_statement
    statement = await self._protocol.prepare(
                ^^^^^^^^^^^^^^^^^^^^^^^^^^^^^
    ...<5 lines>...
    )
    ^
  File "asyncpg/protocol/protocol.pyx", line 165, in prepare
asyncpg.exceptions.UndefinedColumnError: column skill_definitions._metadata does not exist

The above exception was the direct cause of the following exception:

Traceback (most recent call last):
  File "/Users/oliverga/Documents/personal/sworn/venv/lib/python3.13/site-packages/sqlalchemy/engine/base.py", line 1963, in _exec_single_context
    self.dialect.do_execute(
    ~~~~~~~~~~~~~~~~~~~~~~~^
        cursor, str_statement, effective_parameters, context
        ^^^^^^^^^^^^^^^^^^^^^^^^^^^^^^^^^^^^^^^^^^^^^^^^^^^^
    )
    ^
  File "/Users/oliverga/Documents/personal/sworn/venv/lib/python3.13/site-packages/sqlalchemy/engine/default.py", line 943, in do_execute
    cursor.execute(statement, parameters)
    ~~~~~~~~~~~~~~^^^^^^^^^^^^^^^^^^^^^^^
  File "/Users/oliverga/Documents/personal/sworn/venv/lib/python3.13/site-packages/sqlalchemy/dialects/postgresql/asyncpg.py", line 580, in execute
    self._adapt_connection.await_(
    ~~~~~~~~~~~~~~~~~~~~~~~~~~~~~^
        self._prepare_and_execute(operation, parameters)
        ^^^^^^^^^^^^^^^^^^^^^^^^^^^^^^^^^^^^^^^^^^^^^^^^
    )
    ^
  File "/Users/oliverga/Documents/personal/sworn/venv/lib/python3.13/site-packages/sqlalchemy/util/_concurrency_py3k.py", line 132, in await_only
    return current.parent.switch(awaitable)  # type: ignore[no-any-return,attr-defined] # noqa: E501
           ~~~~~~~~~~~~~~~~~~~~~^^^^^^^^^^^
  File "/Users/oliverga/Documents/personal/sworn/venv/lib/python3.13/site-packages/sqlalchemy/util/_concurrency_py3k.py", line 196, in greenlet_spawn
    value = await result
            ^^^^^^^^^^^^
  File "/Users/oliverga/Documents/personal/sworn/venv/lib/python3.13/site-packages/sqlalchemy/dialects/postgresql/asyncpg.py", line 558, in _prepare_and_execute
    self._handle_exception(error)
    ~~~~~~~~~~~~~~~~~~~~~~^^^^^^^
  File "/Users/oliverga/Documents/personal/sworn/venv/lib/python3.13/site-packages/sqlalchemy/dialects/postgresql/asyncpg.py", line 508, in _handle_exception
    self._adapt_connection._handle_exception(error)
    ~~~~~~~~~~~~~~~~~~~~~~~~~~~~~~~~~~~~~~~~^^^^^^^
  File "/Users/oliverga/Documents/personal/sworn/venv/lib/python3.13/site-packages/sqlalchemy/dialects/postgresql/asyncpg.py", line 792, in _handle_exception
    raise translated_error from error
sqlalchemy.dialects.postgresql.asyncpg.AsyncAdapt_asyncpg_dbapi.ProgrammingError: <class 'asyncpg.exceptions.UndefinedColumnError'>: column skill_definitions._metadata does not exist

The above exception was the direct cause of the following exception:

Traceback (most recent call last):
  File "/Users/oliverga/Documents/personal/sworn/app/db/dependencies.py", line 17, in get_async_db
    yield session
  File "/Users/oliverga/Documents/personal/sworn/venv/lib/python3.13/site-packages/fastapi/routing.py", line 301, in app
    raw_response = await run_endpoint_function(
                   ^^^^^^^^^^^^^^^^^^^^^^^^^^^^
    ...<3 lines>...
    )
    ^
  File "/Users/oliverga/Documents/personal/sworn/venv/lib/python3.13/site-packages/fastapi/routing.py", line 212, in run_endpoint_function
    return await dependant.call(**values)
           ^^^^^^^^^^^^^^^^^^^^^^^^^^^^^^
  File "/Users/oliverga/Documents/personal/sworn/app/api/routes/skill_definition_routes.py", line 73, in list_skill_definitions
    skill_defs = await service.get_all_skill_definitions(skip=skip, limit=limit)
                 ^^^^^^^^^^^^^^^^^^^^^^^^^^^^^^^^^^^^^^^^^^^^^^^^^^^^^^^^^^^^^^^
  File "/Users/oliverga/Documents/personal/sworn/app/game_state/services/skill_definition_service.py", line 101, in get_all_skill_definitions
    entities = await self.repository.find_all(skip=skip, limit=limit)
               ^^^^^^^^^^^^^^^^^^^^^^^^^^^^^^^^^^^^^^^^^^^^^^^^^^^^^^
  File "/Users/oliverga/Documents/personal/sworn/app/game_state/repositories/base_repository.py", line 313, in find_all
    result = await self.db.execute(stmt)
             ^^^^^^^^^^^^^^^^^^^^^^^^^^^
  File "/Users/oliverga/Documents/personal/sworn/venv/lib/python3.13/site-packages/sqlalchemy/ext/asyncio/session.py", line 463, in execute
    result = await greenlet_spawn(
             ^^^^^^^^^^^^^^^^^^^^^
    ...<6 lines>...
    )
    ^
  File "/Users/oliverga/Documents/personal/sworn/venv/lib/python3.13/site-packages/sqlalchemy/util/_concurrency_py3k.py", line 201, in greenlet_spawn
    result = context.throw(*sys.exc_info())
  File "/Users/oliverga/Documents/personal/sworn/venv/lib/python3.13/site-packages/sqlalchemy/orm/session.py", line 2365, in execute
    return self._execute_internal(
           ~~~~~~~~~~~~~~~~~~~~~~^
        statement,
        ^^^^^^^^^^
    ...<4 lines>...
        _add_event=_add_event,
        ^^^^^^^^^^^^^^^^^^^^^^
    )
    ^
  File "/Users/oliverga/Documents/personal/sworn/venv/lib/python3.13/site-packages/sqlalchemy/orm/session.py", line 2251, in _execute_internal
    result: Result[Any] = compile_state_cls.orm_execute_statement(
                          ~~~~~~~~~~~~~~~~~~~~~~~~~~~~~~~~~~~~~~~^
        self,
        ^^^^^
    ...<4 lines>...
        conn,
        ^^^^^
    )
    ^
  File "/Users/oliverga/Documents/personal/sworn/venv/lib/python3.13/site-packages/sqlalchemy/orm/context.py", line 306, in orm_execute_statement
    result = conn.execute(
        statement, params or {}, execution_options=execution_options
    )
  File "/Users/oliverga/Documents/personal/sworn/venv/lib/python3.13/site-packages/sqlalchemy/engine/base.py", line 1415, in execute
    return meth(
        self,
        distilled_parameters,
        execution_options or NO_OPTIONS,
    )
  File "/Users/oliverga/Documents/personal/sworn/venv/lib/python3.13/site-packages/sqlalchemy/sql/elements.py", line 523, in _execute_on_connection
    return connection._execute_clauseelement(
           ~~~~~~~~~~~~~~~~~~~~~~~~~~~~~~~~~^
        self, distilled_params, execution_options
        ^^^^^^^^^^^^^^^^^^^^^^^^^^^^^^^^^^^^^^^^^
    )
    ^
  File "/Users/oliverga/Documents/personal/sworn/venv/lib/python3.13/site-packages/sqlalchemy/engine/base.py", line 1637, in _execute_clauseelement
    ret = self._execute_context(
        dialect,
    ...<8 lines>...
        cache_hit=cache_hit,
    )
  File "/Users/oliverga/Documents/personal/sworn/venv/lib/python3.13/site-packages/sqlalchemy/engine/base.py", line 1842, in _execute_context
    return self._exec_single_context(
           ~~~~~~~~~~~~~~~~~~~~~~~~~^
        dialect, context, statement, parameters
        ^^^^^^^^^^^^^^^^^^^^^^^^^^^^^^^^^^^^^^^
    )
    ^
  File "/Users/oliverga/Documents/personal/sworn/venv/lib/python3.13/site-packages/sqlalchemy/engine/base.py", line 1982, in _exec_single_context
    self._handle_dbapi_exception(
    ~~~~~~~~~~~~~~~~~~~~~~~~~~~~^
        e, str_statement, effective_parameters, cursor, context
        ^^^^^^^^^^^^^^^^^^^^^^^^^^^^^^^^^^^^^^^^^^^^^^^^^^^^^^^
    )
    ^
  File "/Users/oliverga/Documents/personal/sworn/venv/lib/python3.13/site-packages/sqlalchemy/engine/base.py", line 2351, in _handle_dbapi_exception
    raise sqlalchemy_exception.with_traceback(exc_info[2]) from e
  File "/Users/oliverga/Documents/personal/sworn/venv/lib/python3.13/site-packages/sqlalchemy/engine/base.py", line 1963, in _exec_single_context
    self.dialect.do_execute(
    ~~~~~~~~~~~~~~~~~~~~~~~^
        cursor, str_statement, effective_parameters, context
        ^^^^^^^^^^^^^^^^^^^^^^^^^^^^^^^^^^^^^^^^^^^^^^^^^^^^
    )
    ^
  File "/Users/oliverga/Documents/personal/sworn/venv/lib/python3.13/site-packages/sqlalchemy/engine/default.py", line 943, in do_execute
    cursor.execute(statement, parameters)
    ~~~~~~~~~~~~~~^^^^^^^^^^^^^^^^^^^^^^^
  File "/Users/oliverga/Documents/personal/sworn/venv/lib/python3.13/site-packages/sqlalchemy/dialects/postgresql/asyncpg.py", line 580, in execute
    self._adapt_connection.await_(
    ~~~~~~~~~~~~~~~~~~~~~~~~~~~~~^
        self._prepare_and_execute(operation, parameters)
        ^^^^^^^^^^^^^^^^^^^^^^^^^^^^^^^^^^^^^^^^^^^^^^^^
    )
    ^
  File "/Users/oliverga/Documents/personal/sworn/venv/lib/python3.13/site-packages/sqlalchemy/util/_concurrency_py3k.py", line 132, in await_only
    return current.parent.switch(awaitable)  # type: ignore[no-any-return,attr-defined] # noqa: E501
           ~~~~~~~~~~~~~~~~~~~~~^^^^^^^^^^^
  File "/Users/oliverga/Documents/personal/sworn/venv/lib/python3.13/site-packages/sqlalchemy/util/_concurrency_py3k.py", line 196, in greenlet_spawn
    value = await result
            ^^^^^^^^^^^^
  File "/Users/oliverga/Documents/personal/sworn/venv/lib/python3.13/site-packages/sqlalchemy/dialects/postgresql/asyncpg.py", line 558, in _prepare_and_execute
    self._handle_exception(error)
    ~~~~~~~~~~~~~~~~~~~~~~^^^^^^^
  File "/Users/oliverga/Documents/personal/sworn/venv/lib/python3.13/site-packages/sqlalchemy/dialects/postgresql/asyncpg.py", line 508, in _handle_exception
    self._adapt_connection._handle_exception(error)
    ~~~~~~~~~~~~~~~~~~~~~~~~~~~~~~~~~~~~~~~~^^^^^^^
  File "/Users/oliverga/Documents/personal/sworn/venv/lib/python3.13/site-packages/sqlalchemy/dialects/postgresql/asyncpg.py", line 792, in _handle_exception
    raise translated_error from error
sqlalchemy.exc.ProgrammingError: (sqlalchemy.dialects.postgresql.asyncpg.ProgrammingError) <class 'asyncpg.exceptions.UndefinedColumnError'>: column skill_definitions._metadata does not exist
[SQL: SELECT skill_definitions.id, skill_definitions.name, skill_definitions.description, skill_definitions.max_level, skill_definitions.themes, skill_definitions._metadata, skill_definitions.created_at, skill_definitions.updated_at 
FROM skill_definitions 
 LIMIT $1::INTEGER OFFSET $2::INTEGER]
[parameters: (100, 0)]
(Background on this error at: https://sqlalche.me/e/20/f405)
2025-05-17 03:34:27,614 - root - INFO - >>> [Dependency] Attempting explicit rollback for session 4495504928...
2025-05-17 03:34:27,614 INFO sqlalchemy.engine.Engine ROLLBACK
2025-05-17 03:34:27,614 - sqlalchemy.engine.Engine - INFO - ROLLBACK
2025-05-17 03:34:27,618 - root - INFO - >>> [Dependency] Explicit rollback successful for session 4495504928.
2025-05-17 03:34:27,618 - root - INFO - >>> [Dependency] Closing session 4495504928...
2025-05-17 03:34:27,618 - root - INFO - >>> [Dependency] Session 4495504928 closed.
2025-05-17 03:34:27,618 - uvicorn.access - INFO - 127.0.0.1:54906 - "GET /api/v1/skills/ HTTP/1.1" 500
2025-05-17 03:34:27,618 - uvicorn.error - ERROR - Exception in ASGI application
Traceback (most recent call last):
  File "/Users/oliverga/Documents/personal/sworn/venv/lib/python3.13/site-packages/sqlalchemy/dialects/postgresql/asyncpg.py", line 521, in _prepare_and_execute
    prepared_stmt, attributes = await adapt_connection._prepare(
                                ^^^^^^^^^^^^^^^^^^^^^^^^^^^^^^^^
        operation, self._invalidate_schema_cache_asof
        ^^^^^^^^^^^^^^^^^^^^^^^^^^^^^^^^^^^^^^^^^^^^^
    )
    ^
  File "/Users/oliverga/Documents/personal/sworn/venv/lib/python3.13/site-packages/sqlalchemy/dialects/postgresql/asyncpg.py", line 768, in _prepare
    prepared_stmt = await self._connection.prepare(
                    ^^^^^^^^^^^^^^^^^^^^^^^^^^^^^^^
        operation, name=self._prepared_statement_name_func()
        ^^^^^^^^^^^^^^^^^^^^^^^^^^^^^^^^^^^^^^^^^^^^^^^^^^^^
    )
    ^
  File "/Users/oliverga/Documents/personal/sworn/venv/lib/python3.13/site-packages/asyncpg/connection.py", line 635, in prepare
    return await self._prepare(
           ^^^^^^^^^^^^^^^^^^^^
    ...<5 lines>...
    )
    ^
  File "/Users/oliverga/Documents/personal/sworn/venv/lib/python3.13/site-packages/asyncpg/connection.py", line 653, in _prepare
    stmt = await self._get_statement(
           ^^^^^^^^^^^^^^^^^^^^^^^^^^
    ...<5 lines>...
    )
    ^
  File "/Users/oliverga/Documents/personal/sworn/venv/lib/python3.13/site-packages/asyncpg/connection.py", line 432, in _get_statement
    statement = await self._protocol.prepare(
                ^^^^^^^^^^^^^^^^^^^^^^^^^^^^^
    ...<5 lines>...
    )
    ^
  File "asyncpg/protocol/protocol.pyx", line 165, in prepare
asyncpg.exceptions.UndefinedColumnError: column skill_definitions._metadata does not exist

The above exception was the direct cause of the following exception:

Traceback (most recent call last):
  File "/Users/oliverga/Documents/personal/sworn/venv/lib/python3.13/site-packages/sqlalchemy/engine/base.py", line 1963, in _exec_single_context
    self.dialect.do_execute(
    ~~~~~~~~~~~~~~~~~~~~~~~^
        cursor, str_statement, effective_parameters, context
        ^^^^^^^^^^^^^^^^^^^^^^^^^^^^^^^^^^^^^^^^^^^^^^^^^^^^
    )
    ^
  File "/Users/oliverga/Documents/personal/sworn/venv/lib/python3.13/site-packages/sqlalchemy/engine/default.py", line 943, in do_execute
    cursor.execute(statement, parameters)
    ~~~~~~~~~~~~~~^^^^^^^^^^^^^^^^^^^^^^^
  File "/Users/oliverga/Documents/personal/sworn/venv/lib/python3.13/site-packages/sqlalchemy/dialects/postgresql/asyncpg.py", line 580, in execute
    self._adapt_connection.await_(
    ~~~~~~~~~~~~~~~~~~~~~~~~~~~~~^
        self._prepare_and_execute(operation, parameters)
        ^^^^^^^^^^^^^^^^^^^^^^^^^^^^^^^^^^^^^^^^^^^^^^^^
    )
    ^
  File "/Users/oliverga/Documents/personal/sworn/venv/lib/python3.13/site-packages/sqlalchemy/util/_concurrency_py3k.py", line 132, in await_only
    return current.parent.switch(awaitable)  # type: ignore[no-any-return,attr-defined] # noqa: E501
           ~~~~~~~~~~~~~~~~~~~~~^^^^^^^^^^^
  File "/Users/oliverga/Documents/personal/sworn/venv/lib/python3.13/site-packages/sqlalchemy/util/_concurrency_py3k.py", line 196, in greenlet_spawn
    value = await result
            ^^^^^^^^^^^^
  File "/Users/oliverga/Documents/personal/sworn/venv/lib/python3.13/site-packages/sqlalchemy/dialects/postgresql/asyncpg.py", line 558, in _prepare_and_execute
    self._handle_exception(error)
    ~~~~~~~~~~~~~~~~~~~~~~^^^^^^^
  File "/Users/oliverga/Documents/personal/sworn/venv/lib/python3.13/site-packages/sqlalchemy/dialects/postgresql/asyncpg.py", line 508, in _handle_exception
    self._adapt_connection._handle_exception(error)
    ~~~~~~~~~~~~~~~~~~~~~~~~~~~~~~~~~~~~~~~~^^^^^^^
  File "/Users/oliverga/Documents/personal/sworn/venv/lib/python3.13/site-packages/sqlalchemy/dialects/postgresql/asyncpg.py", line 792, in _handle_exception
    raise translated_error from error
sqlalchemy.dialects.postgresql.asyncpg.AsyncAdapt_asyncpg_dbapi.ProgrammingError: <class 'asyncpg.exceptions.UndefinedColumnError'>: column skill_definitions._metadata does not exist

The above exception was the direct cause of the following exception:

Traceback (most recent call last):
  File "/Users/oliverga/Documents/personal/sworn/venv/lib/python3.13/site-packages/uvicorn/protocols/http/h11_impl.py", line 403, in run_asgi
    result = await app(  # type: ignore[func-returns-value]
             ^^^^^^^^^^^^^^^^^^^^^^^^^^^^^^^^^^^^^^^^^^^^^^
        self.scope, self.receive, self.send
        ^^^^^^^^^^^^^^^^^^^^^^^^^^^^^^^^^^^
    )
    ^
  File "/Users/oliverga/Documents/personal/sworn/venv/lib/python3.13/site-packages/uvicorn/middleware/proxy_headers.py", line 60, in __call__
    return await self.app(scope, receive, send)
           ^^^^^^^^^^^^^^^^^^^^^^^^^^^^^^^^^^^^
  File "/Users/oliverga/Documents/personal/sworn/venv/lib/python3.13/site-packages/fastapi/applications.py", line 1054, in __call__
    await super().__call__(scope, receive, send)
  File "/Users/oliverga/Documents/personal/sworn/venv/lib/python3.13/site-packages/starlette/applications.py", line 112, in __call__
    await self.middleware_stack(scope, receive, send)
  File "/Users/oliverga/Documents/personal/sworn/venv/lib/python3.13/site-packages/starlette/middleware/errors.py", line 187, in __call__
    raise exc
  File "/Users/oliverga/Documents/personal/sworn/venv/lib/python3.13/site-packages/starlette/middleware/errors.py", line 165, in __call__
    await self.app(scope, receive, _send)
  File "/Users/oliverga/Documents/personal/sworn/venv/lib/python3.13/site-packages/starlette/middleware/cors.py", line 85, in __call__
    await self.app(scope, receive, send)
  File "/Users/oliverga/Documents/personal/sworn/venv/lib/python3.13/site-packages/starlette/middleware/exceptions.py", line 62, in __call__
    await wrap_app_handling_exceptions(self.app, conn)(scope, receive, send)
  File "/Users/oliverga/Documents/personal/sworn/venv/lib/python3.13/site-packages/starlette/_exception_handler.py", line 53, in wrapped_app
    raise exc
  File "/Users/oliverga/Documents/personal/sworn/venv/lib/python3.13/site-packages/starlette/_exception_handler.py", line 42, in wrapped_app
    await app(scope, receive, sender)
  File "/Users/oliverga/Documents/personal/sworn/venv/lib/python3.13/site-packages/starlette/routing.py", line 715, in __call__
    await self.middleware_stack(scope, receive, send)
  File "/Users/oliverga/Documents/personal/sworn/venv/lib/python3.13/site-packages/starlette/routing.py", line 735, in app
    await route.handle(scope, receive, send)
  File "/Users/oliverga/Documents/personal/sworn/venv/lib/python3.13/site-packages/starlette/routing.py", line 288, in handle
    await self.app(scope, receive, send)
  File "/Users/oliverga/Documents/personal/sworn/venv/lib/python3.13/site-packages/starlette/routing.py", line 76, in app
    await wrap_app_handling_exceptions(app, request)(scope, receive, send)
  File "/Users/oliverga/Documents/personal/sworn/venv/lib/python3.13/site-packages/starlette/_exception_handler.py", line 53, in wrapped_app
    raise exc
  File "/Users/oliverga/Documents/personal/sworn/venv/lib/python3.13/site-packages/starlette/_exception_handler.py", line 42, in wrapped_app
    await app(scope, receive, sender)
  File "/Users/oliverga/Documents/personal/sworn/venv/lib/python3.13/site-packages/starlette/routing.py", line 73, in app
    response = await f(request)
               ^^^^^^^^^^^^^^^^
  File "/Users/oliverga/Documents/personal/sworn/venv/lib/python3.13/site-packages/fastapi/routing.py", line 301, in app
    raw_response = await run_endpoint_function(
                   ^^^^^^^^^^^^^^^^^^^^^^^^^^^^
    ...<3 lines>...
    )
    ^
  File "/Users/oliverga/Documents/personal/sworn/venv/lib/python3.13/site-packages/fastapi/routing.py", line 212, in run_endpoint_function
    return await dependant.call(**values)
           ^^^^^^^^^^^^^^^^^^^^^^^^^^^^^^
  File "/Users/oliverga/Documents/personal/sworn/app/api/routes/skill_definition_routes.py", line 73, in list_skill_definitions
    skill_defs = await service.get_all_skill_definitions(skip=skip, limit=limit)
                 ^^^^^^^^^^^^^^^^^^^^^^^^^^^^^^^^^^^^^^^^^^^^^^^^^^^^^^^^^^^^^^^
  File "/Users/oliverga/Documents/personal/sworn/app/game_state/services/skill_definition_service.py", line 101, in get_all_skill_definitions
    entities = await self.repository.find_all(skip=skip, limit=limit)
               ^^^^^^^^^^^^^^^^^^^^^^^^^^^^^^^^^^^^^^^^^^^^^^^^^^^^^^
  File "/Users/oliverga/Documents/personal/sworn/app/game_state/repositories/base_repository.py", line 313, in find_all
    result = await self.db.execute(stmt)
             ^^^^^^^^^^^^^^^^^^^^^^^^^^^
  File "/Users/oliverga/Documents/personal/sworn/venv/lib/python3.13/site-packages/sqlalchemy/ext/asyncio/session.py", line 463, in execute
    result = await greenlet_spawn(
             ^^^^^^^^^^^^^^^^^^^^^
    ...<6 lines>...
    )
    ^
  File "/Users/oliverga/Documents/personal/sworn/venv/lib/python3.13/site-packages/sqlalchemy/util/_concurrency_py3k.py", line 201, in greenlet_spawn
    result = context.throw(*sys.exc_info())
  File "/Users/oliverga/Documents/personal/sworn/venv/lib/python3.13/site-packages/sqlalchemy/orm/session.py", line 2365, in execute
    return self._execute_internal(
           ~~~~~~~~~~~~~~~~~~~~~~^
        statement,
        ^^^^^^^^^^
    ...<4 lines>...
        _add_event=_add_event,
        ^^^^^^^^^^^^^^^^^^^^^^
    )
    ^
  File "/Users/oliverga/Documents/personal/sworn/venv/lib/python3.13/site-packages/sqlalchemy/orm/session.py", line 2251, in _execute_internal
    result: Result[Any] = compile_state_cls.orm_execute_statement(
                          ~~~~~~~~~~~~~~~~~~~~~~~~~~~~~~~~~~~~~~~^
        self,
        ^^^^^
    ...<4 lines>...
        conn,
        ^^^^^
    )
    ^
  File "/Users/oliverga/Documents/personal/sworn/venv/lib/python3.13/site-packages/sqlalchemy/orm/context.py", line 306, in orm_execute_statement
    result = conn.execute(
        statement, params or {}, execution_options=execution_options
    )
  File "/Users/oliverga/Documents/personal/sworn/venv/lib/python3.13/site-packages/sqlalchemy/engine/base.py", line 1415, in execute
    return meth(
        self,
        distilled_parameters,
        execution_options or NO_OPTIONS,
    )
  File "/Users/oliverga/Documents/personal/sworn/venv/lib/python3.13/site-packages/sqlalchemy/sql/elements.py", line 523, in _execute_on_connection
    return connection._execute_clauseelement(
           ~~~~~~~~~~~~~~~~~~~~~~~~~~~~~~~~~^
        self, distilled_params, execution_options
        ^^^^^^^^^^^^^^^^^^^^^^^^^^^^^^^^^^^^^^^^^
    )
    ^
  File "/Users/oliverga/Documents/personal/sworn/venv/lib/python3.13/site-packages/sqlalchemy/engine/base.py", line 1637, in _execute_clauseelement
    ret = self._execute_context(
        dialect,
    ...<8 lines>...
        cache_hit=cache_hit,
    )
  File "/Users/oliverga/Documents/personal/sworn/venv/lib/python3.13/site-packages/sqlalchemy/engine/base.py", line 1842, in _execute_context
    return self._exec_single_context(
           ~~~~~~~~~~~~~~~~~~~~~~~~~^
        dialect, context, statement, parameters
        ^^^^^^^^^^^^^^^^^^^^^^^^^^^^^^^^^^^^^^^
    )
    ^
  File "/Users/oliverga/Documents/personal/sworn/venv/lib/python3.13/site-packages/sqlalchemy/engine/base.py", line 1982, in _exec_single_context
    self._handle_dbapi_exception(
    ~~~~~~~~~~~~~~~~~~~~~~~~~~~~^
        e, str_statement, effective_parameters, cursor, context
        ^^^^^^^^^^^^^^^^^^^^^^^^^^^^^^^^^^^^^^^^^^^^^^^^^^^^^^^
    )
    ^
  File "/Users/oliverga/Documents/personal/sworn/venv/lib/python3.13/site-packages/sqlalchemy/engine/base.py", line 2351, in _handle_dbapi_exception
    raise sqlalchemy_exception.with_traceback(exc_info[2]) from e
  File "/Users/oliverga/Documents/personal/sworn/venv/lib/python3.13/site-packages/sqlalchemy/engine/base.py", line 1963, in _exec_single_context
    self.dialect.do_execute(
    ~~~~~~~~~~~~~~~~~~~~~~~^
        cursor, str_statement, effective_parameters, context
        ^^^^^^^^^^^^^^^^^^^^^^^^^^^^^^^^^^^^^^^^^^^^^^^^^^^^
    )
    ^
  File "/Users/oliverga/Documents/personal/sworn/venv/lib/python3.13/site-packages/sqlalchemy/engine/default.py", line 943, in do_execute
    cursor.execute(statement, parameters)
    ~~~~~~~~~~~~~~^^^^^^^^^^^^^^^^^^^^^^^
  File "/Users/oliverga/Documents/personal/sworn/venv/lib/python3.13/site-packages/sqlalchemy/dialects/postgresql/asyncpg.py", line 580, in execute
    self._adapt_connection.await_(
    ~~~~~~~~~~~~~~~~~~~~~~~~~~~~~^
        self._prepare_and_execute(operation, parameters)
        ^^^^^^^^^^^^^^^^^^^^^^^^^^^^^^^^^^^^^^^^^^^^^^^^
    )
    ^
  File "/Users/oliverga/Documents/personal/sworn/venv/lib/python3.13/site-packages/sqlalchemy/util/_concurrency_py3k.py", line 132, in await_only
    return current.parent.switch(awaitable)  # type: ignore[no-any-return,attr-defined] # noqa: E501
           ~~~~~~~~~~~~~~~~~~~~~^^^^^^^^^^^
  File "/Users/oliverga/Documents/personal/sworn/venv/lib/python3.13/site-packages/sqlalchemy/util/_concurrency_py3k.py", line 196, in greenlet_spawn
    value = await result
            ^^^^^^^^^^^^
  File "/Users/oliverga/Documents/personal/sworn/venv/lib/python3.13/site-packages/sqlalchemy/dialects/postgresql/asyncpg.py", line 558, in _prepare_and_execute
    self._handle_exception(error)
    ~~~~~~~~~~~~~~~~~~~~~~^^^^^^^
  File "/Users/oliverga/Documents/personal/sworn/venv/lib/python3.13/site-packages/sqlalchemy/dialects/postgresql/asyncpg.py", line 508, in _handle_exception
    self._adapt_connection._handle_exception(error)
    ~~~~~~~~~~~~~~~~~~~~~~~~~~~~~~~~~~~~~~~~^^^^^^^
  File "/Users/oliverga/Documents/personal/sworn/venv/lib/python3.13/site-packages/sqlalchemy/dialects/postgresql/asyncpg.py", line 792, in _handle_exception
    raise translated_error from error
sqlalchemy.exc.ProgrammingError: (sqlalchemy.dialects.postgresql.asyncpg.ProgrammingError) <class 'asyncpg.exceptions.UndefinedColumnError'>: column skill_definitions._metadata does not exist
[SQL: SELECT skill_definitions.id, skill_definitions.name, skill_definitions.description, skill_definitions.max_level, skill_definitions.themes, skill_definitions._metadata, skill_definitions.created_at, skill_definitions.updated_at 
FROM skill_definitions 
 LIMIT $1::INTEGER OFFSET $2::INTEGER]
[parameters: (100, 0)]
(Background on this error at: https://sqlalche.me/e/20/f405)
2025-05-17 11:37:38,934 - uvicorn.access - INFO - 127.0.0.1:52250 - "POST /api/v1/skills/skill-definitions HTTP/1.1" 405
2025-05-17 11:46:07,625 - uvicorn.error - INFO - Shutting down
2025-05-17 11:46:07,726 - uvicorn.error - INFO - Waiting for application shutdown.
2025-05-17 11:46:07,726 - uvicorn.error - INFO - Application shutdown complete.
2025-05-17 11:46:07,726 - uvicorn.error - INFO - Finished server process [17250]
